2018-03-19 14:17:29,639 INFO: Microblog startup [in F:\FLASK\Flask_Tutorial\app\__init__.py:44]
2018-03-19 14:18:16,583 INFO: Microblog startup [in F:\FLASK\Flask_Tutorial\app\__init__.py:44]
2018-03-19 14:31:13,982 INFO: Microblog startup [in F:\FLASK\Flask_Tutorial\app\__init__.py:44]
2018-03-19 14:52:33,321 INFO: Microblog startup [in F:\FLASK\Flask_Tutorial\app\__init__.py:44]
2018-03-19 14:54:06,531 INFO: Microblog startup [in F:\FLASK\Flask_Tutorial\app\__init__.py:44]
2018-03-19 14:54:22,017 INFO: Microblog startup [in F:\FLASK\Flask_Tutorial\app\__init__.py:44]
2018-03-19 15:21:37,345 INFO: Microblog startup [in F:\FLASK\Flask_Tutorial\app\__init__.py:44]
2018-03-19 15:37:19,715 INFO: Microblog startup [in F:\FLASK\Flask_Tutorial\app\__init__.py:44]
2018-03-19 15:38:29,837 INFO: Microblog startup [in F:\FLASK\Flask_Tutorial\app\__init__.py:44]
2018-03-19 15:53:26,668 INFO: Microblog startup [in F:\FLASK\Flask_Tutorial\app\__init__.py:44]
2018-03-19 19:29:18,301 INFO: Microblog startup [in /Volumes/ELIAS 2TB H/FLASK/Flask_Tutorial/app/__init__.py:44]
2018-03-19 21:07:04,490 INFO: Microblog startup [in /Volumes/ELIAS 2TB H/FLASK/Flask_Tutorial/app/__init__.py:46]
2018-03-19 21:09:48,016 ERROR: Exception on /reset_password_request [POST] [in /Users/germanaguerra/anaconda2/envs/flask/lib/python3.6/site-packages/flask/app.py:1560]
Traceback (most recent call last):
  File "/Users/germanaguerra/anaconda2/envs/flask/lib/python3.6/site-packages/flask/app.py", line 1982, in wsgi_app
    response = self.full_dispatch_request()
  File "/Users/germanaguerra/anaconda2/envs/flask/lib/python3.6/site-packages/flask/app.py", line 1614, in full_dispatch_request
    rv = self.handle_user_exception(e)
  File "/Users/germanaguerra/anaconda2/envs/flask/lib/python3.6/site-packages/flask/app.py", line 1517, in handle_user_exception
    reraise(exc_type, exc_value, tb)
  File "/Users/germanaguerra/anaconda2/envs/flask/lib/python3.6/site-packages/flask/_compat.py", line 33, in reraise
    raise value
  File "/Users/germanaguerra/anaconda2/envs/flask/lib/python3.6/site-packages/flask/app.py", line 1612, in full_dispatch_request
    rv = self.dispatch_request()
  File "/Users/germanaguerra/anaconda2/envs/flask/lib/python3.6/site-packages/flask/app.py", line 1598, in dispatch_request
    return self.view_functions[rule.endpoint](**req.view_args)
  File "/Volumes/ELIAS 2TB H/FLASK/Flask_Tutorial/app/routes.py", line 160, in reset_password_request
    send_password_reset_email(user)
  File "/Volumes/ELIAS 2TB H/FLASK/Flask_Tutorial/app/email.py", line 21, in send_password_reset_email
    user=user, token=token),
  File "/Volumes/ELIAS 2TB H/FLASK/Flask_Tutorial/app/email.py", line 10, in send_email
    print(`send mail`)
  File "/Users/germanaguerra/anaconda2/envs/flask/lib/python3.6/site-packages/flask_mail.py", line 491, in send
    with self.connect() as connection:
  File "/Users/germanaguerra/anaconda2/envs/flask/lib/python3.6/site-packages/flask_mail.py", line 144, in __enter__
    self.host = self.configure_host()
  File "/Users/germanaguerra/anaconda2/envs/flask/lib/python3.6/site-packages/flask_mail.py", line 158, in configure_host
    host = smtplib.SMTP(self.mail.server, self.mail.port)
  File "/Users/germanaguerra/anaconda2/envs/flask/lib/python3.6/smtplib.py", line 251, in __init__
    (code, msg) = self.connect(host, port)
  File "/Users/germanaguerra/anaconda2/envs/flask/lib/python3.6/smtplib.py", line 336, in connect
    self.sock = self._get_socket(host, port, self.timeout)
  File "/Users/germanaguerra/anaconda2/envs/flask/lib/python3.6/smtplib.py", line 307, in _get_socket
    self.source_address)
  File "/Users/germanaguerra/anaconda2/envs/flask/lib/python3.6/socket.py", line 724, in create_connection
    raise err
  File "/Users/germanaguerra/anaconda2/envs/flask/lib/python3.6/socket.py", line 713, in create_connection
    sock.connect(sa)
TimeoutError: [Errno 60] Operation timed out
2018-03-19 21:10:05,365 INFO: Microblog startup [in /Volumes/ELIAS 2TB H/FLASK/Flask_Tutorial/app/__init__.py:46]
2018-03-19 21:10:29,833 INFO: Microblog startup [in /Volumes/ELIAS 2TB H/FLASK/Flask_Tutorial/app/__init__.py:46]
2018-03-19 21:13:16,249 ERROR: Exception on /reset_password_request [POST] [in /Users/germanaguerra/anaconda2/envs/flask/lib/python3.6/site-packages/flask/app.py:1560]
Traceback (most recent call last):
  File "/Users/germanaguerra/anaconda2/envs/flask/lib/python3.6/site-packages/flask/app.py", line 1982, in wsgi_app
    response = self.full_dispatch_request()
  File "/Users/germanaguerra/anaconda2/envs/flask/lib/python3.6/site-packages/flask/app.py", line 1614, in full_dispatch_request
    rv = self.handle_user_exception(e)
  File "/Users/germanaguerra/anaconda2/envs/flask/lib/python3.6/site-packages/flask/app.py", line 1517, in handle_user_exception
    reraise(exc_type, exc_value, tb)
  File "/Users/germanaguerra/anaconda2/envs/flask/lib/python3.6/site-packages/flask/_compat.py", line 33, in reraise
    raise value
  File "/Users/germanaguerra/anaconda2/envs/flask/lib/python3.6/site-packages/flask/app.py", line 1612, in full_dispatch_request
    rv = self.dispatch_request()
  File "/Users/germanaguerra/anaconda2/envs/flask/lib/python3.6/site-packages/flask/app.py", line 1598, in dispatch_request
    return self.view_functions[rule.endpoint](**req.view_args)
  File "/Volumes/ELIAS 2TB H/FLASK/Flask_Tutorial/app/routes.py", line 160, in reset_password_request
    send_password_reset_email(user)
  File "/Volumes/ELIAS 2TB H/FLASK/Flask_Tutorial/app/email.py", line 23, in send_password_reset_email
    user=user, token=token))
  File "/Volumes/ELIAS 2TB H/FLASK/Flask_Tutorial/app/email.py", line 11, in send_email
    mail.send(msg)
  File "/Users/germanaguerra/anaconda2/envs/flask/lib/python3.6/site-packages/flask_mail.py", line 491, in send
    with self.connect() as connection:
  File "/Users/germanaguerra/anaconda2/envs/flask/lib/python3.6/site-packages/flask_mail.py", line 144, in __enter__
    self.host = self.configure_host()
  File "/Users/germanaguerra/anaconda2/envs/flask/lib/python3.6/site-packages/flask_mail.py", line 158, in configure_host
    host = smtplib.SMTP(self.mail.server, self.mail.port)
  File "/Users/germanaguerra/anaconda2/envs/flask/lib/python3.6/smtplib.py", line 251, in __init__
    (code, msg) = self.connect(host, port)
  File "/Users/germanaguerra/anaconda2/envs/flask/lib/python3.6/smtplib.py", line 336, in connect
    self.sock = self._get_socket(host, port, self.timeout)
  File "/Users/germanaguerra/anaconda2/envs/flask/lib/python3.6/smtplib.py", line 307, in _get_socket
    self.source_address)
  File "/Users/germanaguerra/anaconda2/envs/flask/lib/python3.6/socket.py", line 724, in create_connection
    raise err
  File "/Users/germanaguerra/anaconda2/envs/flask/lib/python3.6/socket.py", line 713, in create_connection
    sock.connect(sa)
TimeoutError: [Errno 60] Operation timed out
